<?xml version="1.0"?>
<sdf version="1.6">
<model name='vehicle_blue' canonical_link='AttachableLink_1_vehicle_1'>
    <link name='AttachableLink_1_vehicle_1'>   
        <pose relative_to='__model__'>0.5 0 0.4 0 0 0</pose> 
        <inertial> <!--inertial properties of the link mass, inertia matix-->
            <mass>1.14395</mass>
            <inertia>
                <ixx>0.126164</ixx>
                <ixy>0</ixy>
                <ixz>0</ixz>
                <iyy>0.416519</iyy>
                <iyz>0</iyz>
                <izz>0.481014</izz>
            </inertia>
        </inertial>
        <visual name='visual'>
            <geometry>
                <box>
                    <size>2.0 1.0 0.5</size> <!--question: this size is in meter-->
                </box>
            </geometry>
            <!--let's add color to our link-->
            <material>
                <ambient>0.0 0.0 1.0 1</ambient>
                <diffuse>0.0 0.0 1.0 1</diffuse>
                <specular>0.0 0.0 1.0 1</specular>
            </material>
        </visual>
        <collision name='collision'> <!--todo: describe why we need the collision-->
            <geometry>
                <box>
                    <size>2.0 1.0 0.5</size>
                </box>
            </geometry>
        </collision>
        <!--sensor name="imu_sensor" type="imu">
            <always_on>1</always_on>
            <update_rate>1</update_rate>
            <visualize>true</visualize>
            <topic>imu</topic>
        </sensor>
        <sensor name='gpu_lidar' type='gpu_lidar'>"
            <pose relative_to='lidar_frame'>0 0 0 0 0 0</pose>
            <topic>lidar</topic>
            <update_rate>10</update_rate>
            <ray>
            <scan>
                <horizontal>
                <samples>640</samples>
                <resolution>1</resolution>
                <min_angle>-1.396263</min_angle>
                <max_angle>1.396263</max_angle>
                </horizontal>
                <vertical>
                <samples>1</samples>
                <resolution>0.01</resolution>
                <min_angle>0</min_angle>
                <max_angle>0</max_angle>
                </vertical>
            </scan>
            <range>
                <min>0.08</min>
                <max>10.0</max>
                <resolution>0.01</resolution>
            </range>
            </ray>
            <alwaysOn>1</alwaysOn>
            <visualize>true</visualize>
        </sensor-->
        <sensor name='sensor_contact' type='contact'>
          <contact>
            <collision>collision</collision>
          </contact>
        </sensor>
    </link>

    <!--let's build the left wheel-->
    <link name='left_wheel'> 
        <pose relative_to="AttachableLink_1_vehicle_1">-0.5 0.6 0 -1.5707 0 0</pose> <!--angles are in radian-->
        <inertial>
            <mass>2</mass>
            <inertia>
                [Build your own robot](SDF_tutorial_link) tutorial. You can download the robot fro   <ixx>0.145833</ixx>
                <ixy>0</ixy>
                <ixz>0</ixz>
                <iyy>0.145833</iyy>
                <iyz>0</iyz>
                <izz>0.125</izz>
            </inertia>
        </inertial>
        <visual name='visual'>
            <geometry>
                <cylinder>
                    <radius>0.4</radius> 
                    <length>0.2</length>
                </cylinder>
            </geometry>
            <material>
                <ambient>1.0 0.0 0.0 1</ambient>
                <diffuse>1.0 0.0 0.0 1</diffuse>
                <specular>1.0 0.0 0.0 1</specular>
            </material>
        </visual>
        <collision name='collision'>
            <geometry>
                <cylinder>
                    <radius>0.4</radius>
                    <length>0.2</length>
                </cylinder>
            </geometry>
        </collision>
    </link>

    <!--copy and paste for right wheel but change position-->
    <link name='right_wheel'>
        <pose relative_to="AttachableLink_1_vehicle_1">-0.5 -0.6 0 -1.5707 0 0</pose> <!--angles are in radian-->
        <inertial>
            <mass>1</mass>
            <inertia>
                <ixx>0.145833</ixx>
                <ixy>0</ixy>
                <ixz>0</ixz>
                <iyy>0.145833</iyy>
                <iyz>0</iyz>
                <izz>0.125</izz>
            </inertia>
        </inertial>
        <visual name='visual'>
            <geometry>
                <cylinder>
                    <radius>0.4</radius>
                    <length>0.2</length>
                </cylinder>
            </geometry>
            <material>
                <ambient>1.0 0.0 0.0 1</ambient>
                <diffuse>1.0 0.0 0.0 1</diffuse>
                <specular>1.0 0.0 0.0 1</specular>
            </material>
        </visual>
        <collision name='collision'>
            <geometry>
                <cylinder>
                    <radius>0.4</radius>
                    <length>0.2</length>
                </cylinder>
            </geometry>
        </collision>
    </link>

    <frame name="caster_frame" attached_to='AttachableLink_1_vehicle_1'>
        <pose>0.8 0 -0.2 0 0 0</pose>
    </frame>

    <!--caster wheel-->
    <link name='caster'>
        <pose relative_to='caster_frame'/>
        <inertial>
            <mass>1</mass>
            <inertia>
                <ixx>0.1</ixx>
                <ixy>0</ixy>
                <ixz>0</ixz>
                <iyy>0.1</iyy>
                <iyz>0</iyz>
                <izz>0.1</izz>
            </inertia>
        </inertial>
        <visual name='visual'>
            <geometry>
                <sphere>
                    <radius>0.2</radius>
                </sphere>
            </geometry>
            <material>
                <ambient>0.0 1 0.0 1</ambient>
                <diffuse>0.0 1 0.0 1 1</diffuse>
                <specular>0.0 1 0.0 1</specular>
            </material>
        </visual>
        <collision name='collision'>
            <geometry>
                <sphere>
                    <radius>0.2</radius>
                </sphere>
            </geometry>
        </collision>
    </link>

    <!--connecting these links together using joints-->
    <joint name='left_wheel_joint' type='revolute'> <!--continous joint is not supported yet-->
        <pose relative_to='left_wheel'/>
        <parent>AttachableLink_1_vehicle_1</parent>
        <child>left_wheel</child>
        <axis>
            <xyz expressed_in='__model__'>0 1 0</xyz> <!--can be descired to any frame or even arbitrary frames-->
            <limit>
                <lower>-1.79769e+308</lower>    <!--negative infinity-->
                <upper>1.79769e+308</upper>     <!--positive infinity-->
            </limit>
        </axis>
    </joint>

    <joint name='right_wheel_joint' type='revolute'>
        <pose relative_to='right_wheel'/>
        <parent>AttachableLink_1_vehicle_1</parent>
        <child>right_wheel</child>
        <axis>
            <xyz expressed_in='__model__'>0 1 0</xyz>
            <limit>
                <lower>-1.79769e+308</lower>    <!--negative infinity-->
                <upper>1.79769e+308</upper>     <!--positive infinity-->
            </limit>
        </axis>
    </joint>

    <!--different type of joints ball joint--> <!--defult value is the child-->
    <joint name='caster_wheel' type='ball'>
        <parent>AttachableLink_1_vehicle_1</parent>
        <child>caster</child>
    </joint>

    <!--diff drive plugin-->
    <plugin
        filename="ignition-gazebo-diff-drive-system"
        name="ignition::gazebo::systems::DiffDrive">
        <left_joint>left_wheel_joint</left_joint>
        <right_joint>right_wheel_joint</right_joint>
        <wheel_separation>1.2</wheel_separation>
        <wheel_radius>0.4</wheel_radius>
        <odom_publish_frequency>1</odom_publish_frequency>
        <topic>cmd_vel</topic>
    </plugin>
</model>
</sdf>   